[2023-05-02T07:02:58.888+0000] {taskinstance.py:1165} INFO - Dependencies all met for <TaskInstance: user_processing.store_users manual__2023-05-02T07:02:52.396312+00:00 [queued]>
[2023-05-02T07:02:58.917+0000] {taskinstance.py:1165} INFO - Dependencies all met for <TaskInstance: user_processing.store_users manual__2023-05-02T07:02:52.396312+00:00 [queued]>
[2023-05-02T07:02:58.918+0000] {taskinstance.py:1362} INFO - 
--------------------------------------------------------------------------------
[2023-05-02T07:02:58.918+0000] {taskinstance.py:1363} INFO - Starting attempt 1 of 1
[2023-05-02T07:02:58.918+0000] {taskinstance.py:1364} INFO - 
--------------------------------------------------------------------------------
[2023-05-02T07:02:58.963+0000] {taskinstance.py:1383} INFO - Executing <Task(PythonOperator): store_users> on 2023-05-02 07:02:52.396312+00:00
[2023-05-02T07:02:58.973+0000] {standard_task_runner.py:55} INFO - Started process 20651 to run task
[2023-05-02T07:02:58.978+0000] {standard_task_runner.py:82} INFO - Running: ['***', 'tasks', 'run', 'user_processing', 'store_users', 'manual__2023-05-02T07:02:52.396312+00:00', '--job-id', '69', '--raw', '--subdir', 'DAGS_FOLDER/processing_user.py', '--cfg-path', '/tmp/tmpgoyzxuua']
[2023-05-02T07:02:58.981+0000] {standard_task_runner.py:83} INFO - Job 69: Subtask store_users
[2023-05-02T07:02:59.123+0000] {task_command.py:376} INFO - Running <TaskInstance: user_processing.store_users manual__2023-05-02T07:02:52.396312+00:00 [running]> on host 9bd2cedcb1a8
[2023-05-02T07:02:59.309+0000] {taskinstance.py:1592} INFO - Exporting the following env vars:
AIRFLOW_CTX_DAG_OWNER=***
AIRFLOW_CTX_DAG_ID=user_processing
AIRFLOW_CTX_TASK_ID=store_users
AIRFLOW_CTX_EXECUTION_DATE=2023-05-02T07:02:52.396312+00:00
AIRFLOW_CTX_TRY_NUMBER=1
AIRFLOW_CTX_DAG_RUN_ID=manual__2023-05-02T07:02:52.396312+00:00
[2023-05-02T07:02:59.311+0000] {taskinstance.py:1851} ERROR - Task failed with exception
Traceback (most recent call last):
  File "/home/airflow/.local/lib/python3.7/site-packages/airflow/operators/python.py", line 175, in execute
    return_value = self.execute_callable()
  File "/home/airflow/.local/lib/python3.7/site-packages/airflow/operators/python.py", line 193, in execute_callable
    return self.python_callable(*self.op_args, **self.op_kwargs)
  File "/opt/airflow/dags/processing_user.py", line 30, in _store_users
    hook = PostgresHook(postgres_conn_id = 'postgres')
NameError: name 'PostgresHook' is not defined
[2023-05-02T07:02:59.341+0000] {taskinstance.py:1406} INFO - Marking task as FAILED. dag_id=user_processing, task_id=store_users, execution_date=20230502T070252, start_date=20230502T070258, end_date=20230502T070259
[2023-05-02T07:02:59.387+0000] {standard_task_runner.py:105} ERROR - Failed to execute job 69 for task store_users (name 'PostgresHook' is not defined; 20651)
[2023-05-02T07:02:59.432+0000] {local_task_job.py:164} INFO - Task exited with return code 1
[2023-05-02T07:02:59.484+0000] {local_task_job.py:273} INFO - 0 downstream tasks scheduled from follow-on schedule check
