[2023-05-01T17:28:25.497+0000] {taskinstance.py:1165} INFO - Dependencies all met for <TaskInstance: user_processing.process_users manual__2023-05-01T17:28:23.511730+00:00 [queued]>
[2023-05-01T17:28:25.510+0000] {taskinstance.py:1165} INFO - Dependencies all met for <TaskInstance: user_processing.process_users manual__2023-05-01T17:28:23.511730+00:00 [queued]>
[2023-05-01T17:28:25.510+0000] {taskinstance.py:1362} INFO - 
--------------------------------------------------------------------------------
[2023-05-01T17:28:25.511+0000] {taskinstance.py:1363} INFO - Starting attempt 1 of 1
[2023-05-01T17:28:25.511+0000] {taskinstance.py:1364} INFO - 
--------------------------------------------------------------------------------
[2023-05-01T17:28:25.530+0000] {taskinstance.py:1383} INFO - Executing <Task(PythonOperator): process_users> on 2023-05-01 17:28:23.511730+00:00
[2023-05-01T17:28:25.536+0000] {standard_task_runner.py:55} INFO - Started process 17822 to run task
[2023-05-01T17:28:25.540+0000] {standard_task_runner.py:82} INFO - Running: ['***', 'tasks', 'run', 'user_processing', 'process_users', 'manual__2023-05-01T17:28:23.511730+00:00', '--job-id', '47', '--raw', '--subdir', 'DAGS_FOLDER/processing_user.py', '--cfg-path', '/tmp/tmpyepp5vke']
[2023-05-01T17:28:25.542+0000] {standard_task_runner.py:83} INFO - Job 47: Subtask process_users
[2023-05-01T17:28:25.626+0000] {task_command.py:376} INFO - Running <TaskInstance: user_processing.process_users manual__2023-05-01T17:28:23.511730+00:00 [running]> on host 9bd2cedcb1a8
[2023-05-01T17:28:25.746+0000] {taskinstance.py:1592} INFO - Exporting the following env vars:
AIRFLOW_CTX_DAG_OWNER=***
AIRFLOW_CTX_DAG_ID=user_processing
AIRFLOW_CTX_TASK_ID=process_users
AIRFLOW_CTX_EXECUTION_DATE=2023-05-01T17:28:23.511730+00:00
AIRFLOW_CTX_TRY_NUMBER=1
AIRFLOW_CTX_DAG_RUN_ID=manual__2023-05-01T17:28:23.511730+00:00
[2023-05-01T17:28:25.766+0000] {taskinstance.py:1851} ERROR - Task failed with exception
Traceback (most recent call last):
  File "/home/airflow/.local/lib/python3.7/site-packages/airflow/operators/python.py", line 175, in execute
    return_value = self.execute_callable()
  File "/home/airflow/.local/lib/python3.7/site-packages/airflow/operators/python.py", line 193, in execute_callable
    return self.python_callable(*self.op_args, **self.op_kwargs)
  File "/opt/airflow/dags/processing_user.py", line 19, in _process_user
    user = user['result'][0]
TypeError: 'NoneType' object is not subscriptable
[2023-05-01T17:28:25.789+0000] {taskinstance.py:1406} INFO - Marking task as FAILED. dag_id=user_processing, task_id=process_users, execution_date=20230501T172823, start_date=20230501T172825, end_date=20230501T172825
[2023-05-01T17:28:25.807+0000] {standard_task_runner.py:105} ERROR - Failed to execute job 47 for task process_users ('NoneType' object is not subscriptable; 17822)
[2023-05-01T17:28:25.833+0000] {local_task_job.py:164} INFO - Task exited with return code 1
[2023-05-01T17:28:25.864+0000] {local_task_job.py:273} INFO - 0 downstream tasks scheduled from follow-on schedule check
